b''b'Traceback (most recent call last):\n  File "/home/q91/OCC-GNN/quiver/dgl_gcn.py", line 344, in <module>\n    last_node_stored = nfeat.clique_tensor_list[0].shard_tensor_config.tensor_offset_device[3].end\nKeyError: 3\n'b'Traceback (most recent call last):\n  File "/home/q91/OCC-GNN/quiver/dgl_gcn.py", line 382, in <module>\n    mp.spawn(\n  File "/home/q91/.local/lib/python3.8/site-packages/torch/multiprocessing/spawn.py", line 230, in spawn\n    return start_processes(fn, args, nprocs, join, daemon, start_method=\'spawn\')\n  File "/home/q91/.local/lib/python3.8/site-packages/torch/multiprocessing/spawn.py", line 188, in start_processes\n    while not context.join():\n  File "/home/q91/.local/lib/python3.8/site-packages/torch/multiprocessing/spawn.py", line 150, in join\n    raise ProcessRaisedException(msg, error_index, failed_process.pid)\ntorch.multiprocessing.spawn.ProcessRaisedException: \n\n-- Process 0 terminated with the following error:\nTraceback (most recent call last):\n  File "/home/q91/.local/lib/python3.8/site-packages/torch/multiprocessing/spawn.py", line 59, in _wrap\n    fn(i, *args)\n  File "/home/q91/OCC-GNN/quiver/dgl_gcn.py", line 253, in run\n    print("epoch:{}".format(average(epoch_time)))\n  File "/home/q91/OCC-GNN/quiver/dgl_gcn.py", line 30, in average\n    return (sum(ls[1:]) -a -b)/(len(ls)-3)\nZeroDivisionError: float division by zero\n\n'b'Traceback (most recent call last):\n  File "/home/q91/OCC-GNN/quiver/dgl_gcn.py", line 382, in <module>\n    mp.spawn(\n  File "/home/q91/.local/lib/python3.8/site-packages/torch/multiprocessing/spawn.py", line 230, in spawn\n    return start_processes(fn, args, nprocs, join, daemon, start_method=\'spawn\')\n  File "/home/q91/.local/lib/python3.8/site-packages/torch/multiprocessing/spawn.py", line 188, in start_processes\n    while not context.join():\n  File "/home/q91/.local/lib/python3.8/site-packages/torch/multiprocessing/spawn.py", line 150, in join\n    raise ProcessRaisedException(msg, error_index, failed_process.pid)\ntorch.multiprocessing.spawn.ProcessRaisedException: \n\n-- Process 0 terminated with the following error:\nTraceback (most recent call last):\n  File "/home/q91/.local/lib/python3.8/site-packages/torch/multiprocessing/spawn.py", line 59, in _wrap\n    fn(i, *args)\n  File "/home/q91/OCC-GNN/quiver/dgl_gcn.py", line 84, in run\n    dist.init_process_group(\'nccl\', rank=rank, world_size=4)\n  File "/home/q91/.local/lib/python3.8/site-packages/torch/distributed/distributed_c10d.py", line 576, in init_process_group\n    store, rank, world_size = next(rendezvous_iterator)\n  File "/home/q91/.local/lib/python3.8/site-packages/torch/distributed/rendezvous.py", line 229, in _env_rendezvous_handler\n    store = _create_c10d_store(master_addr, master_port, rank, world_size, timeout)\n  File "/home/q91/.local/lib/python3.8/site-packages/torch/distributed/rendezvous.py", line 157, in _create_c10d_store\n    return TCPStore(\nRuntimeError: Address already in use\n\n'b'Traceback (most recent call last):\n  File "/home/q91/OCC-GNN/quiver/dgl_gcn.py", line 385, in <module>\n    mp.spawn(\n  File "/home/q91/.local/lib/python3.8/site-packages/torch/multiprocessing/spawn.py", line 230, in spawn\n    return start_processes(fn, args, nprocs, join, daemon, start_method=\'spawn\')\n  File "/home/q91/.local/lib/python3.8/site-packages/torch/multiprocessing/spawn.py", line 188, in start_processes\n    while not context.join():\n  File "/home/q91/.local/lib/python3.8/site-packages/torch/multiprocessing/spawn.py", line 150, in join\n    raise ProcessRaisedException(msg, error_index, failed_process.pid)\ntorch.multiprocessing.spawn.ProcessRaisedException: \n\n-- Process 0 terminated with the following error:\nTraceback (most recent call last):\n  File "/home/q91/.local/lib/python3.8/site-packages/torch/multiprocessing/spawn.py", line 59, in _wrap\n    fn(i, *args)\n  File "/home/q91/OCC-GNN/quiver/dgl_gcn.py", line 85, in run\n    dist.init_process_group(\'nccl\', rank=rank, world_size=4)\n  File "/home/q91/.local/lib/python3.8/site-packages/torch/distributed/distributed_c10d.py", line 576, in init_process_group\n    store, rank, world_size = next(rendezvous_iterator)\n  File "/home/q91/.local/lib/python3.8/site-packages/torch/distributed/rendezvous.py", line 229, in _env_rendezvous_handler\n    store = _create_c10d_store(master_addr, master_port, rank, world_size, timeout)\n  File "/home/q91/.local/lib/python3.8/site-packages/torch/distributed/rendezvous.py", line 157, in _create_c10d_store\n    return TCPStore(\nRuntimeError: Address already in use\n\n'